Workbook

Sheet male_yomi
A1: 読み | B1: 人気 | C1: 件数 | D1: 名前例 | E1: 中性フラグ
A2: こうき | B2: 〇 | C2: 424 | D2: 光輝 光希 光基 光毅 晃毅 幸輝 | E2: =IFERROR(VLOOKUP(A2,female_yomi!A:A,1,FALSE),"") -> こうき
A3: こうじろう | C3: 424 | D3: 幸次郎 浩二郎 孝次郎 康二郎 厚治郎 公次郎 | E3: =IFERROR(VLOOKUP(A3,female_yomi!A:A,1,FALSE),"")
A4: しょうじろう | C4: 388 | D4: 正次郎 昭二郎 翔路朗 翔路郎 照路郎 象二郎 | E4: =IFERROR(VLOOKUP(A4,female_yomi!A:A,1,FALSE),"")
A5: ゆうき | B5: 〇 | C5: 289 | D5: 勇気 勇樹 祐樹 友樹 祐希 優希 | E5: =IFERROR(VLOOKUP(A5,female_yomi!A:A,1,FALSE),"") -> ゆうき
A6: こうじ | C6: 278 | D6: 浩二 康二 浩司 幸司 晃司 倖司 | E6: =IFERROR(VLOOKUP(A6,female_yomi!A:A,1,FALSE),"")
A7: こうせい | B7: 〇 | C7: 257 | D7: 晃生 光正 幸聖 皓誠 倖成 光聖 | E7: =IFERROR(VLOOKUP(A7,female_yomi!A:A,1,FALSE),"")
A8: こうしろう | C8: 241 | D8: 幸志朗 航士朗 倖志郎 功史朗 幸志郎 耕史郎 | E8: =IFERROR(VLOOKUP(A8,female_yomi!A:A,1,FALSE),"")
A9: しょうき | C9: 239 | D9: 将城 翔稀 照生 頌樹 翔麒 翔紀 | E9: =IFERROR(VLOOKUP(A9,female_yomi!A:A,1,FALSE),"")
A10: けいじろう | C10: 219 | D10: 啓次郎 啓二朗 経二郎 桂志郎 慶二郎 慶治朗 | E10: =IFERROR(VLOOKUP(A10,female_yomi!A:A,1,FALSE),"")
A11: しょうじ | C11: 215 | D11: 昭二 昭治 捷爾 庄治 庄司 正司 | E11: =IFERROR(VLOOKUP(A11,female_yomi!A:A,1,FALSE),"")
A12: しょうせい | C12: 211 | D12: 翔聖 祥生 翔星 聖星 翔征 渉世 | E12: =IFERROR(VLOOKUP(A12,female_yomi!A:A,1,FALSE),"")
A13: ひろき | C13: 202 | D13: 弘樹 宏樹 浩紀 大樹 大輝 洋貴 | E13: =IFERROR(VLOOKUP(A13,female_yomi!A:A,1,FALSE),"") -> ひろき
A14: こうすけ | C14: 196 | D14: 康介 浩介 孝介 幸介 航佑 浩輔 | E14: =IFERROR(VLOOKUP(A14,female_yomi!A:A,1,FALSE),"")
A15: ゆうせい | B15: 〇 | C15: 190 | D15: 優征 佑星 悠誠 雄星 優成 優星 | E15: =IFERROR(VLOOKUP(A15,female_yomi!A:A,1,FALSE),"")
A16: よしひろ | C16: 183 | D16: 義弘 佳宏 吉寛 吉弘 善弘 義広 | E16: =IFERROR(VLOOKUP(A16,female_yomi!A:A,1,FALSE),"")
A17: けんしょう | C17: 181 | D17: 賢 将 憲章 賢 尚兼 史 鷹 顕 章顕 昭 | E17: =IFERROR(VLOOKUP(A17,female_yomi!A:A,1,FALSE),"")
A18: よしき | C18: 180 | D18: 良樹 芳樹 由紀 佳喜 佳季 佳樹 | E18: =IFERROR(VLOOKUP(A18,female_yomi!A:A,1,FALSE),"")
A19: あきひろ | C19: 179 | D19: 秋博 彰宏 昭宏 彰広 明宏 明洋 | E19: =IFERROR(VLOOKUP(A19,female_yomi!A:A,1,FALSE),"")
A20: しょうけん | C20: 179 | D20: 正見 匠見 翔賢 翔剣 翔兼 翔健 | E20: =IFERROR(VLOOKUP(A20,female_yomi!A:A,1,FALSE),"")
A21: けんき | C21: 166 | D21: 建樹 建紀 賢貴 研輝 堅樹 健起 | E21: =IFERROR(VLOOKUP(A21,female_yomi!A:A,1,FALSE),"")
A22: けんじ | C22: 165 | D22: 健二 賢治 健司 健治 賢二 研二 | E22: =IFERROR(VLOOKUP(A22,female_yomi!A:A,1,FALSE),"")
A23: きくま | C23: 163 | D23: 菊 磨毅 来 真 毅 久 麻希 来 眞起 来 眞喜 来 磨 | E23: =IFERROR(VLOOKUP(A23,female_yomi!A:A,1,FALSE),"")
A24: はるき | B24: 〇 | C24: 154 | D24: 陽葵 春樹 晴喜 晴樹 陽輝 遥喜 | E24: =IFERROR(VLOOKUP(A24,female_yomi!A:A,1,FALSE),"") -> はるき
A25: まさき | C25: 146 | D25: 正樹 雅樹 正輝 将喜 将希 雅紀 | E25: =IFERROR(VLOOKUP(A25,female_yomi!A:A,1,FALSE),"") -> まさき
A26: りょうせい | C26: 146 | D26: 遼青 綾成 亮青 涼青 稜青 良青 | E26: =IFERROR(VLOOKUP(A26,female_yomi!A:A,1,FALSE),"")
A27: けいしょう | C27: 145 | D27: 慶祥 桂章 慶照 慶尚 圭尚 圭将 | E27: =IFERROR(VLOOKUP(A27,female_yomi!A:A,1,FALSE),"")
A28: けんのすけ | C28: 145 | D28: 健之丞 憲之典 健之佑 賢之丞 拳之介 憲之介 | E28: =IFERROR(VLOOKUP(A28,female_yomi!A:A,1,FALSE),"")
A29: よしのり | C29: 145 | D29: 義則 由紀 義徳 良則 美徳 善紀 | E29: =IFERROR(VLOOKUP(A29,female_yomi!A:A,1,FALSE),"")
A30: たかし | C30: 143 | D30: 隆 孝 隆 史 崇高 志 孝 志 | E30: =IFERROR(VLOOKUP(A30,female_yomi!A:A,1,FALSE),"")
A31: けいじ | C31: 142 | D31: 敬司 啓二 慶二 佳治 啓司 啓次 | E31: =IFERROR(VLOOKUP(A31,female_yomi!A:A,1,FALSE),"")
A32: たかひろ | C32: 141 | D32: 貴弘 享祐 孝宏 孝弘 崇裕 貴博 | E32: =IFERROR(VLOOKUP(A32,female_yomi!A:A,1,FALSE),"")
A33: けんしろう | C33: 139 | D33: 健史朗 健士朗 健士郎 顕嗣朗 兼嗣郎 健史郎 | E33: =IFERROR(VLOOKUP(A33,female_yomi!A:A,1,FALSE),"")
A34: ゆうじ | C34: 136 | D34: 雄二 裕二 祐二 雄司 有志 優二 | E34: =IFERROR(VLOOKUP(A34,female_yomi!A:A,1,FALSE),"")
A35: あきじ | C35: 132 | D35: 秋児 彰路 章志 明治 秋司 秋二 | E35: =IFERROR(VLOOKUP(A35,female_yomi!A:A,1,FALSE),"")
A36: ひろし | C36: 132 | D36: 博 弘 宏 浩浩 志 寛 | E36: =IFERROR(VLOOKUP(A36,female_yomi!A:A,1,FALSE),"")
... A57: あきら | C57: 105 | D57: 明 晃 彰 啓 昭 信 | E57: =IFERROR(VLOOKUP(A57,female_yomi!A:A,1,FALSE),"") -> あきら
A58: ひろと | B58: 〇 | C58: 105 | D58: 大翔 滉斗 博人 寛人 悠人 宏斗 | E58: =IFERROR(VLOOKUP(A58,female_yomi!A:A,1,FALSE),"")
A59: ゆうま | B59: 〇 | C59: 105 | D59: 悠真 勇馬 佑真 悠馬 優馬 優磨 | E59: =IFERROR(VLOOKUP(A59,female_yomi!A:A,1,FALSE),"")
A60: さとし | C60: 104 | D60: 聡 慧 智 悟 志 知 智 史 | E60: =IFERROR(VLOOKUP(A60,female_yomi!A:A,1,FALSE),"")
...

Sheet female_yomi
A1: 読み | B1: 人気 | C1: 件数 | D1: 名前例 | E1: 中性フラグ
A2: きゆか | C2: 1560 | D2: 樹弓香 貴結可 輝結花 希夕可 稀優花 樹友嘉 | E2: =IFERROR(VLOOKUP(A2,male_yomi!A:A,1,FALSE),"")
A3: きりか | C3: 887 | D3: 桐花 紀 璃 花霧 香季 里香 輝 莉香 貴 理香 | E3: =IFERROR(VLOOKUP(A3,male_yomi!A:A,1,FALSE),"")
A4: さゆか | C4: 781 | D4: 彩由佳 佐優香 沙友果 早由華 沙結耶 紗結香 | E4: =IFERROR(VLOOKUP(A4,male_yomi!A:A,1,FALSE),"")
A5: ゆりか | C5: 683 | D5: 優理香 百合香 優里佳 友理佳 百合華 夕理華 | E5: =IFERROR(VLOOKUP(A5,male_yomi!A:A,1,FALSE),"")
A6: えりか | C6: 606 | D6: 絵梨花 恵里香 枝里香 愛莉花 恵梨香 依里佳 | E6: =IFERROR(VLOOKUP(A6,male_yomi!A:A,1,FALSE),"")
A7: あゆき | C7: 581 | D7: 彩 侑 生 愛 雪愛 幸安 夕 妃安 祐 妃 明 来 | E7: =IFERROR(VLOOKUP(A7,male_yomi!A:A,1,FALSE),"") -> あゆき
A8: まゆか | C8: 496 | D8: 麻由佳 舞弓夏 真由香 茉由香 麻由香 茉侑佳 | E8: =IFERROR(VLOOKUP(A8,male_yomi!A:A,1,FALSE),"")
A9: さゆり | C9: 479 | D9: 小百合 沙百合 彩有里 彩百合 早百合 紗有里 | E9: =IFERROR(VLOOKUP(A9,male_yomi!A:A,1,FALSE),"")
A10: るなか | C10: 472 | D10: 流七花 流夏歌 瑠七香 瑠奈花 瑠奈夏 瑠奈加 | E10: =IFERROR(VLOOKUP(A10,male_yomi!A:A,1,FALSE),"")
A11: ゆかほ | C11: 468 | D11: 友香歩 祐嘉保 由花歩 友嘉帆 友嘉穂 友嘉歩 | E11: =IFERROR(VLOOKUP(A11,male_yomi!A:A,1,FALSE),"")
A12: ゆりま | C12: 460 | D12: 祐利真 由里麻 友里麻 友里眞 友里真 友里茉 | E12: =IFERROR(VLOOKUP(A12,male_yomi!A:A,1,FALSE),"")
A13: ゆきえ | C13: 444 | D13: 幸 恵 幸枝 幸江 優 希恵 幸絵 由紀 恵 | E13: =IFERROR(VLOOKUP(A13,male_yomi!A:A,1,FALSE),"") -> ゆきえ
... A16: まりか | C16: 405 | D16: 茉莉花 万理華 真梨香 真理香 | E16: =IFERROR(VLOOKUP(A16,male_yomi!A:A,1,FALSE),"")
A17: あかり | B17: 〇 | C17: 394 | D17: 朱莉 朱里 灯 明 明里 朱梨 | E17: =IFERROR(VLOOKUP(A17,male_yomi!A:A,1,FALSE),"") -> あかり
A18: まきか | C18: 388 | D18: 真貴香 真貴加 真紀花 真稀香 真稀華 真稀花 | E18: =IFERROR(VLOOKUP(A18,male_yomi!A:A,1,FALSE),"")
A19: ゆみか | C19: 388 | D19: 弓 佳 弓夏 弓香 裕 美佳 優 海華 結 未香 | E19: =IFERROR(VLOOKUP(A19,male_yomi!A:A,1,FALSE),"")
A20: ゆきほ | C20: 383 | D20: 幸 穂幸 保 千 穂 結 稀 歩雪 穂 侑 紀 保 | E20: =IFERROR(VLOOKUP(A20,male_yomi!A:A,1,FALSE),"")
A21: あゆか | C21: 381 | D21: 亜優 花亜 優香 彩 優花 彩 結花 愛 優 花歩 佳 | E21: =IFERROR(VLOOKUP(A21,male_yomi!A:A,1,FALSE),"") -> あゆか
A22: さえり | C22: 380 | D22: 紗衣莉 紗衣理 紗江理 紗恵里 紗恵理 咲英里 | E22: =IFERROR(VLOOKUP(A22,male_yomi!A:A,1,FALSE),"")
A23: ゆきみ | C23: 372 | D23: 雪 美雪 海 唯希 実 結 喜海 弓喜 美幸 実 | E23: =IFERROR(VLOOKUP(A23,male_yomi!A:A,1,FALSE),"") -> ゆきみ
A24: さりか | C24: 362 | D24: 咲里花 紗里香 紗里華 紗里花 紗里夏 紗里加 | E24: =IFERROR(VLOOKUP(A24,male_yomi!A:A,1,FALSE),"")
A25: きゆみ | C25: 351 | D25: 貴有美 妃友美 稀唯海 喜弓海 季悠美 希夕実 | E25: =IFERROR(VLOOKUP(A25,male_yomi!A:A,1,FALSE),"")
A26: ゆなか | C26: 351 | D26: 友奈果 夕菜華 友菜花 友菜香 友菜加 友菜果 | E26: =IFERROR(VLOOKUP(A26,male_yomi!A:A,1,FALSE),"")
A27: えまり | C27: 340 | D27: 衣 真里 絵毬 恵 舞利 衣鞠 衣茉 里衣 茉莉 | E27: =IFERROR(VLOOKUP(A27,male_yomi!A:A,1,FALSE),"")
A28: ゆりほ | C28: 336 | D28: 裕璃穂 結里帆 由里帆 由莉帆 友里帆 友里穂 | E28: =IFERROR(VLOOKUP(A28,male_yomi!A:A,1,FALSE),"")
A29: さきか | C29: 327 | D29: 咲花 早季 加咲 貴 花咲 香紗 貴 香紗 貴花 | E29: =IFERROR(VLOOKUP(A29,male_yomi!A:A,1,FALSE),"")
... A136: あやか | C136: 123 | D136: 綾香 彩花 彩佳 彩夏 彩香 綾華 | E136: =IFERROR(VLOOKUP(A136,male_yomi!A:A,1,FALSE),"")
A137: ゆいか | B137: 〇 | C137: 122 | D137: 結 香 結 華 唯花 結 花由 衣歌 優 依花 | E137: =IFERROR(VLOOKUP(A137,male_yomi!A:A,1,FALSE),"")
A138: ゆか | C138: 122 | D138: 由夏 由佳 由香 結花 有香 友香 | E138: =IFERROR(VLOOKUP(A138,male_yomi!A:A,1,FALSE),"")
A139: まえみ | C139: 121 | D139: 真絵美 万恵美 麻絵美 茉恵美 真恵美 真恵実 | E139: =IFERROR(VLOOKUP(A139,male_yomi!A:A,1,FALSE),"")
A140: りみか | C140: 121 | D140: 梨美華 凜巳花 里美香 里美華 里美花 里美果 | E140: =IFERROR(VLOOKUP(A140,male_yomi!A:A,1,FALSE),"")
A141: かほな | C141: 120 | D141: 香穂奈 香歩菜 華穂菜 香帆奈 嘉帆菜 嘉帆那 | E141: =IFERROR(VLOOKUP(A141,male_yomi!A:A,1,FALSE),"")
A142: まりあ | C142: 120 | D142: 麻里 亜毬 愛 真 理 亜 真 理 愛 真 莉 愛茉 梨亜 | E142: =IFERROR(VLOOKUP(A142,male_yomi!A:A,1,FALSE),"")
A143: まりえ | C143: 120 | D143: 万里江 万里絵 真梨恵 真理恵 真里恵 麻理恵 | E143: =IFERROR(VLOOKUP(A143,male_yomi!A:A,1,FALSE),"")
A144: ゆきこ | C144: 119 | D144: 優 希子 由紀 子雪 子幸 子由 希子 有 希子 | E144: =IFERROR(VLOOKUP(A144,male_yomi!A:A,1,FALSE),"")
A145: ゆなみ | C145: 119 | D145: 由波 結 菜美 結 菜実 結 波 祐 菜美 由 奈美 | E145: =IFERROR(VLOOKUP(A145,male_yomi!A:A,1,FALSE),"")
A146: ゆうか | C146: 118 | D146: 優香 優花 夕夏 優華 友香 悠香 | E146: =IFERROR(VLOOKUP(A146,male_yomi!A:A,1,FALSE),"") -> ゆうか
A147: きみよ | C147: 117 | D147: 妃 未代 貴 実代 紀 美代 希 美代 君代 貴 美代 | E147: =IFERROR(VLOOKUP(A147,male_yomi!A:A,1,FALSE),"")
A148: しきな | C148: 117 | D148: 志希菜 詩稀菜 志紀奈 詩貴那 詩樹菜 詩樹奈 | E148: =IFERROR(VLOOKUP(A148,male_yomi!A:A,1,FALSE),"")
...
